Workbook

Sheet Summary
A1: END_TR_BALANCE Reconciliation Check
A2: Tolerance ($) | B2: 0.05 | C2: Input (assumption): rounding tolerance - change if needed
A4: Result | B4: Rows | C4: % of checked
A5: PASS | B5: =COUNTIF(Check!$T$2:$T$5000,A5) -> 17 | C5: =IF($B$8=0,0,B5/$B$8) -> 0.39534884
A6: FAIL | B6: =COUNTIF(Check!$T$2:$T$5000,A6) -> 24 | C6: =IF($B$8=0,0,B6/$B$8) -> 0.55813953
A7: BYPASS | B7: =COUNTIF(Check!$T$2:$T$5000,A7) -> 2 | C7: =IF($B$8=0,0,B7/$B$8) -> 0.046511628
A8: Total | B8: =SUM(B5:B7) -> 43
A10: Formula used (per tranche)
A11: Expected_ETB = PreV_ETB - PRINCIPAL_DIST - CURR_REALIZED_LOSS + Deferred_interest (blank/NULL treated as 0)
A12: PASS: |End_tr_balance - Expected_ETB| <= tolerance FAIL: otherwise BYPASS: PreV_ETB or End_tr_balance is missing (cannot test)
A14: How to use
A15: 1) Paste your full table (same 17 columns, A:Q, headers in row 1) over the sample rows on the Check sheet. 2) Columns R:U calculate automatically (formulas filled to row 5000). 3) Filter column T for FAIL / BYPASS.
A16: The 43 rows currently on Check are a sample taken from your data, shown only as an example.

Sheet Check
A1: DEAL_ID | B1: Deal_Name | C1: Deal_Type | D1: Month | E1: Year | F1: Status | G1: FORMATE_Name | H1: Cash_Flow | I1: TRANCHE_ID | J1: TRANCHE_NAME | K1: beginning_balance | L1: End_tr_balance | M1: Notional_Balance | N1: PRINCIPAL_DIST | O1: CURR_REALIZED_LOSS | P1: Deferred_interest | Q1: PreV_ETB | R1: Expected_ETB | S1: Diff (Reported - Expected) | T1: Result | U1: Reason
A2: 8441 | B2: Countrywide MBS 1998-12 | C2: WL | D2: 9 | E2: 2026 | F2: UPLOADED | G2: BNY_FORMAT_4 | H2: PI | I2: 251785 | J2: X1 | K2: 23990.95 | L2: 0 | M2: 21599.43 | N2: 0 | O2: 0 | P2: 0 | Q2: 0 | R2: =IF(AND(A2<>"",ISNUMBER(Q2),ISNUMBER(L2)),ROUND(Q2-IF(ISNUMBER(N2),N2,0)-IF(ISNUMBER(O2),O2,0)+IF(ISNUMBER(P2),P2,0),2),"") -> 0 | S2: =IF(R2="","",ROUND(L2-R2,2)) -> 0 | T2: =IF(A2="","",IF(S2="","BYPASS",IF(ABS(S2)<=Summary!$B$2,"PASS","FAIL"))) -> PASS | U2: =IF(T2="BYPASS",IF(NOT(ISNUMBER(Q2)),"PreV_ETB missing","End_tr_balance missing"),IF(T2="FAIL",IF(AND(ISNUMBER(K2),ISNUMBER(L2),ABS(L2-(K2-IF(ISNUMBER(N2),N2,0)-IF(ISNUMBER(O2),O2,0)+IF(ISNUMBER(P2),P2,0)))<=Summary!$B$2),"Passes using beginning_balance - PreV_ETB differs from beginning_balance",IF(AND(ISNUMBER(O2),O2<0,ABS(L2-(Q2-IF(ISNUMBER(N2),N2,0)+IF(ISNUMBER(P2),P2,0)))<=Summary!$B$2),"Negative realized loss not applied - check sign",IF(R2<0,"Principal paid exceeds prior balance",IF(AND(L2>Q2,NOT(ISNUMBER(P2))),"Balance increased but no Deferred_interest reported",IF(L2>R2,"Reported balance higher than expected (missing increase/OC build)","Reported balance lower than expected (missing decrease)"))))),""))
A3: 8763 | B3: ABS Corp Equity Loan Trust 1999-LB1 | C3: WL | D3: 9 | E3: 2026 | F3: UPLOADED | G3: JP_Format_2 | H3: PI | I3: 256328 | J3: B-1F | K3: 928526.63 | L3: 915905.81 | M3: 915905.81 | N3: 12315.89 | O3: 304.93 | P3: 0 | Q3: 928526.63 | R3: =IF(AND(A3<>"",ISNUMBER(Q3),ISNUMBER(L3)),ROUND(Q3-IF(ISNUMBER(N3),N3,0)-IF(ISNUMBER(O3),O3,0)+IF(ISNUMBER(P3),P3,0),2),"") -> 915905.81 | S3: =IF(R3="","",ROUND(L3-R3,2)) -> 0 | T3: =IF(A3="","",IF(S3="","BYPASS",IF(ABS(S3)<=Summary!$B$2,"PASS","FAIL"))) -> PASS | U3: =IF(T3="BYPASS",IF(NOT(ISNUMBER(Q3)),"PreV_ETB missing","End_tr_balance missing"),IF(T3="FAIL",IF(AND(ISNUMBER(K3),ISNUMBER(L3),ABS(L3-(K3-IF(ISNUMBER(N3),N3,0)-IF(ISNUMBER(O3),O3,0)+IF(ISNUMBER(P3),P3,0)))<=Summary!$B$2),"Passes using beginning_balance - PreV_ETB differs from beginning_balance",IF(AND(ISNUMBER(O3),O3<0,ABS(L3-(Q3-IF(ISNUMBER(N3),N3,0)+IF(ISNUMBER(P3),P3,0)))<=Summary!$B$2),"Negative realized loss not applied - check sign",IF(R3<0,"Principal paid exceeds prior balance",IF(AND(L3>Q3,NOT(ISNUMBER(P3))),"Balance increased but no Deferred_interest reported",IF(L3>R3,"Reported balance higher than expected (missing increase/OC build)","Reported balance lower than expected (missing decrease)"))))),""))
A4: 9071 | B4: RFMSII 2000-HI2 | C4: WL | D4: 9 | E4: 2026 | F4: UPLOADED | G4: GMAC_Format_6 | H4: PI | I4: 258674 | J4: CERTS | K4: 13330.64 | L4: 13286.86 | M4: NULL | N4: 43.78 | O4: 137.9 | P4: 137.9 | Q4: 13330.64 | R4: =IF(AND(A4<>"",ISNUMBER(Q4),ISNUMBER(L4)),ROUND(Q4-IF(ISNUMBER(N4),N4,0)-IF(ISNUMBER(O4),O4,0)+IF(ISNUMBER(P4),P4,0),2),"") -> 13286.86 | S4: =IF(R4="","",ROUND(L4-R4,2)) -> 0 | T4: =IF(A4="","",IF(S4="","BYPASS",IF(ABS(S4)<=Summary!$B$2,"PASS","FAIL"))) -> PASS | U4: =IF(T4="BYPASS",IF(NOT(ISNUMBER(Q4)),"PreV_ETB missing","End_tr_balance missing"),IF(T4="FAIL",IF(AND(ISNUMBER(K4),ISNUMBER(L4),ABS(L4-(K4-IF(ISNUMBER(N4),N4,0)-IF(ISNUMBER(O4),O4,0)+IF(ISNUMBER(P4),P4,0)))<=Summary!$B$2),"Passes using beginning_balance - PreV_ETB differs from beginning_balance",IF(AND(ISNUMBER(O4),O4<0,ABS(L4-(Q4-IF(ISNUMBER(N4),N4,0)+IF(ISNUMBER(P4),P4,0)))<=Summary!$B$2),"Negative realized loss not applied - check sign",IF(R4<0,"Principal paid exceeds prior balance",IF(AND(L4>Q4,NOT(ISNUMBER(P4))),"Balance increased but no Deferred_interest reported",IF(L4>R4,"Reported balance higher than expected (missing increase/OC build)","Reported balance lower than expected (missing decrease)"))))),""))
A5: 10667 | B5: RAMP 2001-RS2 | C5: WL | D5: 9 | E5: 2026 | F5: UPLOADED | G5: DM_GMAC_FORMAT_1 | H5: PI | I5: 273119 | J5: SB-II | K5: 316551.6 | L5: 312129.55 | M5: NULL | N5: 4853.23 | O5: 0 | P5: 431.18 | Q5: 316551.6 | R5: =IF(AND(A5<>"",ISNUMBER(Q5),ISNUMBER(L5)),ROUND(Q5-IF(ISNUMBER(N5),N5,0)-IF(ISNUMBER(O5),O5,0)+IF(ISNUMBER(P5),P5,0),2),"") -> 312129.55 | S5: =IF(R5="","",ROUND(L5-R5,2)) -> 0 | T5: =IF(A5="","",IF(S5="","BYPASS",IF(ABS(S5)<=Summary!$B$2,"PASS","FAIL"))) -> PASS | U5: =IF(T5="BYPASS",IF(NOT(ISNUMBER(Q5)),"PreV_ETB missing","End_tr_balance missing"),IF(T5="FAIL",IF(AND(ISNUMBER(K5),ISNUMBER(L5),ABS(L5-(K5-IF(ISNUMBER(N5),N5,0)-IF(ISNUMBER(O5),O5,0)+IF(ISNUMBER(P5),P5,0)))<=Summary!$B$2),"Passes using beginning_balance - PreV_ETB differs from beginning_balance",IF(AND(ISNUMBER(O5),O5<0,ABS(L5-(Q5-IF(ISNUMBER(N5),N5,0)+IF(ISNUMBER(P5),P5,0)))<=Summary!$B$2),"Negative realized loss not applied - check sign",IF(R5<0,"Principal paid exceeds prior balance",IF(AND(L5>Q5,NOT(ISNUMBER(P5))),"Balance increased but no Deferred_interest reported",IF(L5>R5,"Reported balance higher than expected (missing increase/OC build)","Reported balance lower than expected (missing decrease)"))))),""))
A6: 11103 | B6: RAMP 2001-RS3 | C6: WL | D6: 9 | E6: 2026 | F6: UPLOADED | G6: DM_JP_Format_1 | H6: PI | I6: 276476 | J6: SB-I | K6: 1087625 | L6: 1077868.6 | M6: NULL | N6: 10893.09 | O6: 0 | P6: 1136.73 | Q6: 1087625 | R6: =IF(AND(A6<>"",ISNUMBER(Q6),ISNUMBER(L6)),ROUND(Q6-IF(ISNUMBER(N6),N6,0)-IF(ISNUMBER(O6),O6,0)+IF(ISNUMBER(P6),P6,0),2),"") -> 1077868.6 | S6: =IF(R6="","",ROUND(L6-R6,2)) -> 0 | T6: =IF(A6="","",IF(S6="","BYPASS",IF(ABS(S6)<=Summary!$B$2,"PASS","FAIL"))) -> PASS | U6: =IF(T6="BYPASS",IF(NOT(ISNUMBER(Q6)),"PreV_ETB missing","End_tr_balance missing"),IF(T6="FAIL",IF(AND(ISNUMBER(K6),ISNUMBER(L6),ABS(L6-(K6-IF(ISNUMBER(N6),N6,0)-IF(ISNUMBER(O6),O6,0)+IF(ISNUMBER(P6),P6,0)))<=Summary!$B$2),"Passes using beginning_balance - PreV_ETB differs from beginning_balance",IF(AND(ISNUMBER(O6),O6<0,ABS(L6-(Q6-IF(ISNUMBER(N6),N6,0)+IF(ISNUMBER(P6),P6,0)))<=Summary!$B$2),"Negative realized loss not applied - check sign",IF(R6<0,"Principal paid exceeds prior balance",IF(AND(L6>Q6,NOT(ISNUMBER(P6))),"Balance increased but no Deferred_interest reported",IF(L6>R6,"Reported balance higher than expected (missing increase/OC build)","Reported balance lower than expected (missing decrease)"))))),""))
A7: 11374 | B7: Ameriquest 2001-A | C7: WL | D7: 9 | E7: 2026 | F7: UPLOADED | G7: DB_FORMAT_1 | H7: PI | I7: 278791 | J7: CE | K7: 1386201.6 | L7: 1391725.1 | M7: NULL | N7: 0 | O7: 0 | P7: 5523.58 | Q7: 1386201.6 | R7: =IF(AND(A7<>"",ISNUMBER(Q7),ISNUMBER(L7)),ROUND(Q7-IF(ISNUMBER(N7),N7,0)-IF(ISNUMBER(O7),O7,0)+IF(ISNUMBER(P7),P7,0),2),"") -> 1391725.1 | S7: =IF(R7="","",ROUND(L7-R7,2)) -> 0 | T7: =IF(A7="","",IF(S7="","BYPASS",IF(ABS(S7)<=Summary!$B$2,"PASS","FAIL"))) -> PASS | U7: =IF(T7="BYPASS",IF(NOT(ISNUMBER(Q7)),"PreV_ETB missing","End_tr_balance missing"),IF(T7="FAIL",IF(AND(ISNUMBER(K7),ISNUMBER(L7),ABS(L7-(K7-IF(ISNUMBER(N7),N7,0)-IF(ISNUMBER(O7),O7,0)+IF(ISNUMBER(P7),P7,0)))<=Summary!$B$2),"Passes using beginning_balance - PreV_ETB differs from beginning_balance",IF(AND(ISNUMBER(O7),O7<0,ABS(L7-(Q7-IF(ISNUMBER(N7),N7,0)+IF(ISNUMBER(P7),P7,0)))<=Summary!$B$2),"Negative realized loss not applied - check sign",IF(R7<0,"Principal paid exceeds prior balance",IF(AND(L7>Q7,NOT(ISNUMBER(P7))),"Balance increased but no Deferred_interest reported",IF(L7>R7,"Reported balance higher than expected (missing increase/OC build)","Reported balance lower than expected (missing decrease)"))))),""))
A8: 11421 | B8: MSDWC 2001-NC4 | C8: WL | D8: 9 | E8: 2026 | F8: UPLOADED | G8: US_Format_Special_1 | H8: PI | I8: 1514213 | J8: X | K8: 1233607.8 | L8: 1237770.5 | M8: NULL | N8: 0 | O8: 0 | P8: NULL | Q8: 1233607.8 | R8: =IF(AND(A8<>"",ISNUMBER(Q8),ISNUMBER(L8)),ROUND(Q8-IF(ISNUMBER(N8),N8,0)-IF(ISNUMBER(O8),O8,0)+IF(ISNUMBER(P8),P8,0),2),"") -> 1233607.8 | S8: =IF(R8="","",ROUND(L8-R8,2)) -> 4162.75 | T8: =IF(A8="","",IF(S8="","BYPASS",IF(ABS(S8)<=Summary!$B$2,"PASS","FAIL"))) -> FAIL | U8: =IF(T8="BYPASS",IF(NOT(ISNUMBER(Q8)),"PreV_ETB missing","End_tr_balance missing"),IF(T8="FAIL",IF(AND(ISNUMBER(K8),ISNUMBER(L8),ABS(L8-(K8-IF(ISNUMBER(N8),N8,0)-IF(ISNUMBER(O8),O8,0)+IF(ISNUMBER(P8),P8,0)))<=Summary!$B$2),"Passes using beginning_balance - PreV_ETB differs from beginning_balance",IF(AND(ISNUMBER(O8),O8<0,ABS(L8-(Q8-IF(ISNUMBER(N8),N8,0)+IF(ISNUMBER(P8),P8,0)))<=Summary!$B$2),"Negative realized loss not applied - check sign",IF(R8<0,"Principal paid exceeds prior balance",IF(AND(L8>Q8,NOT(ISNUMBER(P8))),"Balance increased but no Deferred_interest reported",IF(L8>R8,"Reported balance higher than expected (missing increase/OC build)","Reported balance lower than expected (missing decrease)"))))),"")) -> Balance increased but no Deferred_interest reported
A9: 11543 | B9: Merrill Lynch 2002-AFC1 | C9: WL | D9: 9 | E9: 2026 | F9: UPLOADED | G9: DM_US_Format_7 | H9: PI | I9: 280462 | J9: C | K9: 5990652.3 | L9: 5934675.9 | M9: NULL | N9: 0 | O9: 0 | P9: NULL | Q9: 5990652.3 | R9: =IF(AND(A9<>"",ISNUMBER(Q9),ISNUMBER(L9)),ROUND(Q9-IF(ISNUMBER(N9),N9,0)-IF(ISNUMBER(O9),O9,0)+IF(ISNUMBER(P9),P9,0),2),"") -> 5990652.3 | S9: =IF(R9="","",ROUND(L9-R9,2)) -> -55976.45 | T9: =IF(A9="","",IF(S9="","BYPASS",IF(ABS(S9)<=Summary!$B$2,"PASS","FAIL"))) -> FAIL | U9: =IF(T9="BYPASS",IF(NOT(ISNUMBER(Q9)),"PreV_ETB missing","End_tr_balance missing"),IF(T9="FAIL",IF(AND(ISNUMBER(K9),ISNUMBER(L9),ABS(L9-(K9-IF(ISNUMBER(N9),N9,0)-IF(ISNUMBER(O9),O9,0)+IF(ISNUMBER(P9),P9,0)))<=Summary!$B$2),"Passes using beginning_balance - PreV_ETB differs from beginning_balance",IF(AND(ISNUMBER(O9),O9<0,ABS(L9-(Q9-IF(ISNUMBER(N9),N9,0)+IF(ISNUMBER(P9),P9,0)))<=Summary!$B$2),"Negative realized loss not applied - check sign",IF(R9<0,"Principal paid exceeds prior balance",IF(AND(L9>Q9,NOT(ISNUMBER(P9))),"Balance increased but no Deferred_interest reported",IF(L9>R9,"Reported balance higher than expected (missing increase/OC build)","Reported balance lower than expected (missing decrease)"))))),"")) -> Reported balance lower than expected (missing decrease)
A10: 11549 | B10: New Century 2002-1 | C10: WL | D10: 9 | E10: 2026 | F10: UPLOADED | G10: US_Format_7 | H10: PI | I10: 1514121 | J10: CE | K10: 378786.58 | L10: 376732.52 | M10: NULL | N10: 0 | O10: 1523 | P10: NULL | Q10: 378786.58 | R10: =IF(AND(A10<>"",ISNUMBER(Q10),ISNUMBER(L10)),ROUND(Q10-IF(ISNUMBER(N10),N10,0)-IF(ISNUMBER(O10),O10,0)+IF(ISNUMBER(P10),P10,0),2),"") -> 377263.58 | S10: =IF(R10="","",ROUND(L10-R10,2)) -> -531.06 | T10: =IF(A10="","",IF(S10="","BYPASS",IF(ABS(S10)<=Summary!$B$2,"PASS","FAIL"))) -> FAIL | U10: =IF(T10="BYPASS",IF(NOT(ISNUMBER(Q10)),"PreV_ETB missing","End_tr_balance missing"),IF(T10="FAIL",IF(AND(ISNUMBER(K10),ISNUMBER(L10),ABS(L10-(K10-IF(ISNUMBER(N10),N10,0)-IF(ISNUMBER(O10),O10,0)+IF(ISNUMBER(P10),P10,0)))<=Summary!$B$2),"Passes using beginning_balance - PreV_ETB differs from beginning_balance",IF(AND(ISNUMBER(O10),O10<0,ABS(L10-(Q10-IF(ISNUMBER(N10),N10,0)+IF(ISNUMBER(P10),P10,0)))<=Summary!$B$2),"Negative realized loss not applied - check sign",IF(R10<0,"Principal paid exceeds prior balance",IF(AND(L10>Q10,NOT(ISNUMBER(P10))),"Balance increased but no Deferred_interest reported",IF(L10>R10,"Reported balance higher than expected (missing increase/OC build)","Reported balance lower than expected (missing decrease)"))))),"")) -> Reported balance lower than expected (missing decrease)
A11: 11600 | B11: RAMP 2002-RP1 | C11: WL | D11: 9 | E11: 2026 | F11: UPLOADED | G11: JP_Format_1 | H11: PI | I11: 280874 | J11: SB | K11: 535585.77 | L11: 535585.77 | M11: NULL | N11: 843.17 | O11: 0 | P11: 843.17 | Q11: 535585.77 | R11: =IF(AND(A11<>"",ISNUMBER(Q11),ISNUMBER(L11)),ROUND(Q11-IF(ISNUMBER(N11),N11,0)-IF(ISNUMBER(O11),O11,0)+IF(ISNUMBER(P11),P11,0),2),"") -> 535585.77 | S11: =IF(R11="","",ROUND(L11-R11,2)) -> 0 | T11: =IF(A11="","",IF(S11="","BYPASS",IF(ABS(S11)<=Summary!$B$2,"PASS","FAIL"))) -> PASS | U11: =IF(T11="BYPASS",IF(NOT(ISNUMBER(Q11)),"PreV_ETB missing","End_tr_balance missing"),IF(T11="FAIL",IF(AND(ISNUMBER(K11),ISNUMBER(L11),ABS(L11-(K11-IF(ISNUMBER(N11),N11,0)-IF(ISNUMBER(O11),O11,0)+IF(ISNUMBER(P11),P11,0)))<=Summary!$B$2),"Passes using beginning_balance - PreV_ETB differs from beginning_balance",IF(AND(ISNUMBER(O11),O11<0,ABS(L11-(Q11-IF(ISNUMBER(N11),N11,0)+IF(ISNUMBER(P11),P11,0)))<=Summary!$B$2),"Negative realized loss not applied - check sign",IF(R11<0,"Principal paid exceeds prior balance",IF(AND(L11>Q11,NOT(ISNUMBER(P11))),"Balance increased but no Deferred_interest reported",IF(L11>R11,"Reported balance higher than expected (missing increase/OC build)","Reported balance lower than expected (missing decrease)"))))),""))
A12: 11865 | B12: MSDWC 2002-HE1 | C12: WL | D12: 9 | E12: 2026 | F12: UPLOADED | G12: US_Format_Special_1 | H12: PI | I12: 1514091 | J12: X | K12: 2551903.2 | L12: 2516726.2 | M12: 2516726.2 | N12: 0 | O12: 35176.91 | P12: NULL | Q12: 2551903.2 | R12: =IF(AND(A12<>"",ISNUMBER(Q12),ISNUMBER(L12)),ROUND(Q12-IF(ISNUMBER(N12),N12,0)-IF(ISNUMBER(O12),O12,0)+IF(ISNUMBER(P12),P12,0),2),"") -> 2516726.2 | S12: =IF(R12="","",ROUND(L12-R12,2)) -> 0 | T12: =IF(A12="","",IF(S12="","BYPASS",IF(ABS(S12)<=Summary!$B$2,"PASS","FAIL"))) -> PASS | U12: =IF(T12="BYPASS",IF(NOT(ISNUMBER(Q12)),"PreV_ETB missing","End_tr_balance missing"),IF(T12="FAIL",IF(AND(ISNUMBER(K12),ISNUMBER(L12),ABS(L12-(K12-IF(ISNUMBER(N12),N12,0)-IF(ISNUMBER(O12),O12,0)+IF(ISNUMBER(P12),P12,0)))<=Summary!$B$2),"Passes using beginning_balance - PreV_ETB differs from beginning_balance",IF(AND(ISNUMBER(O12),O12<0,ABS(L12-(Q12-IF(ISNUMBER(N12),N12,0)+IF(ISNUMBER(P12),P12,0)))<=Summary!$B$2),"Negative realized loss not applied - check sign",IF(R12<0,"Principal paid exceeds prior balance",IF(AND(L12>Q12,NOT(ISNUMBER(P12))),"Balance increased but no Deferred_interest reported",IF(L12>R12,"Reported balance higher than expected (missing increase/OC build)","Reported balance lower than expected (missing decrease)"))))),""))
A13: 11976 | B13: RFMSII 2002-HI1 | C13: WL | D13: 9 | E13: 2026 | F13: UPLOADED | G13: GMAC_Format_4 | H13: PI | I13: 283981 | J13: CERTS | K13: 51350.29 | L13: 49625.6 | M13: NULL | N13: 1724.69 | O13: 575.63 | P13: 575.63 | Q13: 51350.29 | R13: =IF(AND(A13<>"",ISNUMBER(Q13),ISNUMBER(L13)),ROUND(Q13-IF(ISNUMBER(N13),N13,0)-IF(ISNUMBER(O13),O13,0)+IF(ISNUMBER(P13),P13,0),2),"") -> 49625.6 | S13: =IF(R13="","",ROUND(L13-R13,2)) -> 0 | T13: =IF(A13="","",IF(S13="","BYPASS",IF(ABS(S13)<=Summary!$B$2,"PASS","FAIL"))) -> PASS | U13: =IF(T13="BYPASS",IF(NOT(ISNUMBER(Q13)),"PreV_ETB missing","End_tr_balance missing"),IF(T13="FAIL",IF(AND(ISNUMBER(K13),ISNUMBER(L13),ABS(L13-(K13-IF(ISNUMBER(N13),N13,0)-IF(ISNUMBER(O13),O13,0)+IF(ISNUMBER(P13),P13,0)))<=Summary!$B$2),"Passes using beginning_balance - PreV_ETB differs from beginning_balance",IF(AND(ISNUMBER(O13),O13<0,ABS(L13-(Q13-IF(ISNUMBER(N13),N13,0)+IF(ISNUMBER(P13),P13,0)))<=Summary!$B$2),"Negative realized loss not applied - check sign",IF(R13<0,"Principal paid exceeds prior balance",IF(AND(L13>Q13,NOT(ISNUMBER(P13))),"Balance increased but no Deferred_interest reported",IF(L13>R13,"Reported balance higher than expected (missing increase/OC build)","Reported balance lower than expected (missing decrease)"))))),""))
A14: 11979 | B14: RFMSII 2002-HI3 | C14: WL | D14: 9 | E14: 2026 | F14: UPLOADED | G14: GMAC_Format_4 | H14: PI | I14: 284005 | J14: CERTS | K14: 27302.31 | L14: 26152.89 | M14: NULL | N14: 1149.42 | O14: 2441.7 | P14: 2441.7 | Q14: 27302.31 | R14: =IF(AND(A14<>"",ISNUMBER(Q14),ISNUMBER(L14)),ROUND(Q14-IF(ISNUMBER(N14),N14,0)-IF(ISNUMBER(O14),O14,0)+IF(ISNUMBER(P14),P14,0),2),"") -> 26152.89 | S14: =IF(R14="","",ROUND(L14-R14,2)) -> 0 | T14: =IF(A14="","",IF(S14="","BYPASS",IF(ABS(S14)<=Summary!$B$2,"PASS","FAIL"))) -> PASS | U14: =IF(T14="BYPASS",IF(NOT(ISNUMBER(Q14)),"PreV_ETB missing","End_tr_balance missing"),IF(T14="FAIL",IF(AND(ISNUMBER(K14),ISNUMBER(L14),ABS(L14-(K14-IF(ISNUMBER(N14),N14,0)-IF(ISNUMBER(O14),O14,0)+IF(ISNUMBER(P14),P14,0)))<=Summary!$B$2),"Passes using beginning_balance - PreV_ETB differs from beginning_balance",IF(AND(ISNUMBER(O14),O14<0,ABS(L14-(Q14-IF(ISNUMBER(N14),N14,0)+IF(ISNUMBER(P14),P14,0)))<=Summary!$B$2),"Negative realized loss not applied - check sign",IF(R14<0,"Principal paid exceeds prior balance",IF(AND(L14>Q14,NOT(ISNUMBER(P14))),"Balance increased but no Deferred_interest reported",IF(L14>R14,"Reported balance higher than expected (missing increase/OC build)","Reported balance lower than expected (missing decrease)"))))),""))
A15: 17544 | B15: MASTR ABS 2003-WMC2 | C15: WL | D15: 9 | E15: 2026 | F15: UPLOADED | G15: DM_US_Format_9 | H15: PI | I15: 467559 | J15: CE | K15: 1559816.9 | L15: 1944846.4 | M15: NULL | N15: 0 | O15: 0 | P15: NULL | Q15: 1559816.9 | R15: =IF(AND(A15<>"",ISNUMBER(Q15),ISNUMBER(L15)),ROUND(Q15-IF(ISNUMBER(N15),N15,0)-IF(ISNUMBER(O15),O15,0)+IF(ISNUMBER(P15),P15,0),2),"") -> 1559816.9 | S15: =IF(R15="","",ROUND(L15-R15,2)) -> 385029.54 | T15: =IF(A15="","",IF(S15="","BYPASS",IF(ABS(S15)<=Summary!$B$2,"PASS","FAIL"))) -> FAIL | U15: =IF(T15="BYPASS",IF(NOT(ISNUMBER(Q15)),"PreV_ETB missing","End_tr_balance missing"),IF(T15="FAIL",IF(AND(ISNUMBER(K15),ISNUMBER(L15),ABS(L15-(K15-IF(ISNUMBER(N15),N15,0)-IF(ISNUMBER(O15),O15,0)+IF(ISNUMBER(P15),P15,0)))<=Summary!$B$2),"Passes using beginning_balance - PreV_ETB differs from beginning_balance",IF(AND(ISNUMBER(O15),O15<0,ABS(L15-(Q15-IF(ISNUMBER(N15),N15,0)+IF(ISNUMBER(P15),P15,0)))<=Summary!$B$2),"Negative realized loss not applied - check sign",IF(R15<0,"Principal paid exceeds prior balance",IF(AND(L15>Q15,NOT(ISNUMBER(P15))),"Balance increased but no Deferred_interest reported",IF(L15>R15,"Reported balance higher than expected (missing increase/OC build)","Reported balance lower than expected (missing decrease)"))))),"")) -> Balance increased but no Deferred_interest reported
A16: 33396 | B16: Countrywide MBS 2005-HYB1 | C16: WL | D16: 9 | E16: 2026 | F16: UPLOADED | G16: BNY_FORMAT_4 | H16: PI | I16: 371291 | J16: 1X | K16: 3625077.3 | L16: 17235.15 | M16: 3586699.9 | N16: 101.11 | O16: 0 | P16: 0 | Q16: 17336.26 | R16: =IF(AND(A16<>"",ISNUMBER(Q16),ISNUMBER(L16)),ROUND(Q16-IF(ISNUMBER(N16),N16,0)-IF(ISNUMBER(O16),O16,0)+IF(ISNUMBER(P16),P16,0),2),"") -> 17235.15 | S16: =IF(R16="","",ROUND(L16-R16,2)) -> 0 | T16: =IF(A16="","",IF(S16="","BYPASS",IF(ABS(S16)<=Summary!$B$2,"PASS","FAIL"))) -> PASS | U16: =IF(T16="BYPASS",IF(NOT(ISNUMBER(Q16)),"PreV_ETB missing","End_tr_balance missing"),IF(T16="FAIL",IF(AND(ISNUMBER(K16),ISNUMBER(L16),ABS(L16-(K16-IF(ISNUMBER(N16),N16,0)-IF(ISNUMBER(O16),O16,0)+IF(ISNUMBER(P16),P16,0)))<=Summary!$B$2),"Passes using beginning_balance - PreV_ETB differs from beginning_balance",IF(AND(ISNUMBER(O16),O16<0,ABS(L16-(Q16-IF(ISNUMBER(N16),N16,0)+IF(ISNUMBER(P16),P16,0)))<=Summary!$B$2),"Negative realized loss not applied - check sign",IF(R16<0,"Principal paid exceeds prior balance",IF(AND(L16>Q16,NOT(ISNUMBER(P16))),"Balance increased but no Deferred_interest reported",IF(L16>R16,"Reported balance higher than expected (missing increase/OC build)","Reported balance lower than expected (missing decrease)"))))),""))
A17: 33428 | B17: WaMu 2005-AR2 | C17: WL | D17: 9 | E17: 2026 | F17: UPLOADED | G17: WAMU_Format_1 | H17: PI | I17: 371799 | J17: B1 | K17: 44004023 | L17: 43402472 | M17: NULL | N17: 242433.39 | O17: 425752.43 | P17: NULL | Q17: 44004023 | R17: =IF(AND(A17<>"",ISNUMBER(Q17),ISNUMBER(L17)),ROUND(Q17-IF(ISNUMBER(N17),N17,0)-IF(ISNUMBER(O17),O17,0)+IF(ISNUMBER(P17),P17,0),2),"") -> 43335838 | S17: =IF(R17="","",ROUND(L17-R17,2)) -> 66634.22 | T17: =IF(A17="","",IF(S17="","BYPASS",IF(ABS(S17)<=Summary!$B$2,"PASS","FAIL"))) -> FAIL | U17: =IF(T17="BYPASS",IF(NOT(ISNUMBER(Q17)),"PreV_ETB missing","End_tr_balance missing"),IF(T17="FAIL",IF(AND(ISNUMBER(K17),ISNUMBER(L17),ABS(L17-(K17-IF(ISNUMBER(N17),N17,0)-IF(ISNUMBER(O17),O17,0)+IF(ISNUMBER(P17),P17,0)))<=Summary!$B$2),"Passes using beginning_balance - PreV_ETB differs from beginning_balance",IF(AND(ISNUMBER(O17),O17<0,ABS(L17-(Q17-IF(ISNUMBER(N17),N17,0)+IF(ISNUMBER(P17),P17,0)))<=Summary!$B$2),"Negative realized loss not applied - check sign",IF(R17<0,"Principal paid exceeds prior balance",IF(AND(L17>Q17,NOT(ISNUMBER(P17))),"Balance increased but no Deferred_interest reported",IF(L17>R17,"Reported balance higher than expected (missing increase/OC build)","Reported balance lower than expected (missing decrease)"))))),"")) -> Reported balance higher than expected (missing increase/OC build)
A18: 33613 | B18: Encore Credit 2005-1 | C18: WL | D18: 9 | E18: 2026 | F18: UPLOADED | G18: DM_BNY_FORMAT_3 | H18: PI | I18: 465149 | J18: C-1 | K18: 510.35 | L18: 7033.51 | M18: NULL | N18: 0 | O18: 0 | P18: 0 | Q18: 510.35 | R18: =IF(AND(A18<>"",ISNUMBER(Q18),ISNUMBER(L18)),ROUND(Q18-IF(ISNUMBER(N18),N18,0)-IF(ISNUMBER(O18),O18,0)+IF(ISNUMBER(P18),P18,0),2),"") -> 510.35 | S18: =IF(R18="","",ROUND(L18-R18,2)) -> 6523.16 | T18: =IF(A18="","",IF(S18="","BYPASS",IF(ABS(S18)<=Summary!$B$2,"PASS","FAIL"))) -> FAIL | U18: =IF(T18="BYPASS",IF(NOT(ISNUMBER(Q18)),"PreV_ETB missing","End_tr_balance missing"),IF(T18="FAIL",IF(AND(ISNUMBER(K18),ISNUMBER(L18),ABS(L18-(K18-IF(ISNUMBER(N18),N18,0)-IF(ISNUMBER(O18),O18,0)+IF(ISNUMBER(P18),P18,0)))<=Summary!$B$2),"Passes using beginning_balance - PreV_ETB differs from beginning_balance",IF(AND(ISNUMBER(O18),O18<0,ABS(L18-(Q18-IF(ISNUMBER(N18),N18,0)+IF(ISNUMBER(P18),P18,0)))<=Summary!$B$2),"Negative realized loss not applied - check sign",IF(R18<0,"Principal paid exceeds prior balance",IF(AND(L18>Q18,NOT(ISNUMBER(P18))),"Balance increased but no Deferred_interest reported",IF(L18>R18,"Reported balance higher than expected (missing increase/OC build)","Reported balance lower than expected (missing decrease)"))))),"")) -> Reported balance higher than expected (missing increase/OC build)
A19: 33936 | B19: First Franklin 2004-FF10 | C19: WL | D19: 9 | E19: 2026 | F19: UPLOADED | G19: JP_Format_1 | H19: PI | I19: 1511198 | J19: CE | K19: 573929.18 | L19: 421948.87 | M19: NULL | N19: 0 | O19: 0 | P19: 0 | Q19: 573929.18 | R19: =IF(AND(A19<>"",ISNUMBER(Q19),ISNUMBER(L19)),ROUND(Q19-IF(ISNUMBER(N19),N19,0)-IF(ISNUMBER(O19),O19,0)+IF(ISNUMBER(P19),P19,0),2),"") -> 573929.18 | S19: =IF(R19="","",ROUND(L19-R19,2)) -> -151980.31 | T19: =IF(A19="","",IF(S19="","BYPASS",IF(ABS(S19)<=Summary!$B$2,"PASS","FAIL"))) -> FAIL | U19: =IF(T19="BYPASS",IF(NOT(ISNUMBER(Q19)),"PreV_ETB missing","End_tr_balance missing"),IF(T19="FAIL",IF(AND(ISNUMBER(K19),ISNUMBER(L19),ABS(L19-(K19-IF(ISNUMBER(N19),N19,0)-IF(ISNUMBER(O19),O19,0)+IF(ISNUMBER(P19),P19,0)))<=Summary!$B$2),"Passes using beginning_balance - PreV_ETB differs from beginning_balance",IF(AND(ISNUMBER(O19),O19<0,ABS(L19-(Q19-IF(ISNUMBER(N19),N19,0)+IF(ISNUMBER(P19),P19,0)))<=Summary!$B$2),"Negative realized loss not applied - check sign",IF(R19<0,"Principal paid exceeds prior balance",IF(AND(L19>Q19,NOT(ISNUMBER(P19))),"Balance increased but no Deferred_interest reported",IF(L19>R19,"Reported balance higher than expected (missing increase/OC build)","Reported balance lower than expected (missing decrease)"))))),"")) -> Reported balance lower than expected (missing decrease)
A20: 34334 | B20: GMACM HEL 2005-HE2 | C20: WL | D20: 9 | E20: 2026 | F20: UPLOADED | G20: GMAC_Format_1 | H20: PI | I20: 382212 | J20: A-4 | K20: 2874831.9 | L20: 2810258.6 | M20: NULL | N20: 69135.1 | O20: 0 | P20: 0 | Q20: 2874831.9 | R20: =IF(AND(A20<>"",ISNUMBER(Q20),ISNUMBER(L20)),ROUND(Q20-IF(ISNUMBER(N20),N20,0)-IF(ISNUMBER(O20),O20,0)+IF(ISNUMBER(P20),P20,0),2),"") -> 2805696.8 | S20: =IF(R20="","",ROUND(L20-R20,2)) -> 4561.77 | T20: =IF(A20="","",IF(S20="","BYPASS",IF(ABS(S20)<=Summary!$B$2,"PASS","FAIL"))) -> FAIL | U20: =IF(T20="BYPASS",IF(NOT(ISNUMBER(Q20)),"PreV_ETB missing","End_tr_balance missing"),IF(T20="FAIL",IF(AND(ISNUMBER(K20),ISNUMBER(L20),ABS(L20-(K20-IF(ISNUMBER(N20),N20,0)-IF(ISNUMBER(O20),O20,0)+IF(ISNUMBER(P20),P20,0)))<=Summary!$B$2),"Passes using beginning_balance - PreV_ETB differs from beginning_balance",IF(AND(ISNUMBER(O20),O20<0,ABS(L20-(Q20-IF(ISNUMBER(N20),N20,0)+IF(ISNUMBER(P20),P20,0)))<=Summary!$B$2),"Negative realized loss not applied - check sign",IF(R20<0,"Principal paid exceeds prior balance",IF(AND(L20>Q20,NOT(ISNUMBER(P20))),"Balance increased but no Deferred_interest reported",IF(L20>R20,"Reported balance higher than expected (missing increase/OC build)","Reported balance lower than expected (missing decrease)"))))),"")) -> Reported balance higher than expected (missing increase/OC build)
A21: 34556 | B21: GSR 2005-1F | C21: WL | D21: 9 | E21: 2026 | F21: UPLOADED | G21: JP_Format_2 | H21: PI | I21: 385396 | J21: IIIA3 | K21: 1370015.4 | L21: 1354716.6 | M21: NULL | N21: 23418.91 | O21: -1269.95 | P21: 6850.08 | Q21: 1370015.4 | R21: =IF(AND(A21<>"",ISNUMBER(Q21),ISNUMBER(L21)),ROUND(Q21-IF(ISNUMBER(N21),N21,0)-IF(ISNUMBER(O21),O21,0)+IF(ISNUMBER(P21),P21,0),2),"") -> 1354716.6 | S21: =IF(R21="","",ROUND(L21-R21,2)) -> 0 | T21: =IF(A21="","",IF(S21="","BYPASS",IF(ABS(S21)<=Summary!$B$2,"PASS","FAIL"))) -> PASS | U21: =IF(T21="BYPASS",IF(NOT(ISNUMBER(Q21)),"PreV_ETB missing","End_tr_balance missing"),IF(T21="FAIL",IF(AND(ISNUMBER(K21),ISNUMBER(L21),ABS(L21-(K21-IF(ISNUMBER(N21),N21,0)-IF(ISNUMBER(O21),O21,0)+IF(ISNUMBER(P21),P21,0)))<=Summary!$B$2),"Passes using beginning_balance - PreV_ETB differs from beginning_balance",IF(AND(ISNUMBER(O21),O21<0,ABS(L21-(Q21-IF(ISNUMBER(N21),N21,0)+IF(ISNUMBER(P21),P21,0)))<=Summary!$B$2),"Negative realized loss not applied - check sign",IF(R21<0,"Principal paid exceeds prior balance",IF(AND(L21>Q21,NOT(ISNUMBER(P21))),"Balance increased but no Deferred_interest reported",IF(L21>R21,"Reported balance higher than expected (missing increase/OC build)","Reported balance lower than expected (missing decrease)"))))),""))
A22: 33091 | B22: RAMP 2004-SL4 | C22: WL | D22: 9 | E22: 2026 | F22: UPLOADED | G22: GMAC_Format_2 | H22: PI | I22: 367303 | J22: A-III | K22: 0 | L22: 1169.49 | M22: NULL | N22: 0 | O22: 0 | P22: 0 | Q22: 0 | R22: =IF(AND(A22<>"",ISNUMBER(Q22),ISNUMBER(L22)),ROUND(Q22-IF(ISNUMBER(N22),N22,0)-IF(ISNUMBER(O22),O22,0)+IF(ISNUMBER(P22),P22,0),2),"") -> 0 | S22: =IF(R22="","",ROUND(L22-R22,2)) -> 1169.49 | T22: =IF(A22="","",IF(S22="","BYPASS",IF(ABS(S22)<=Summary!$B$2,"PASS","FAIL"))) -> FAIL | U22: =IF(T22="BYPASS",IF(NOT(ISNUMBER(Q22)),"PreV_ETB missing","End_tr_balance missing"),IF(T22="FAIL",IF(AND(ISNUMBER(K22),ISNUMBER(L22),ABS(L22-(K22-IF(ISNUMBER(N22),N22,0)-IF(ISNUMBER(O22),O22,0)+IF(ISNUMBER(P22),P22,0)))<=Summary!$B$2),"Passes using beginning_balance - PreV_ETB differs from beginning_balance",IF(AND(ISNUMBER(O22),O22<0,ABS(L22-(Q22-IF(ISNUMBER(N22),N22,0)+IF(ISNUMBER(P22),P22,0)))<=Summary!$B$2),"Negative realized loss not applied - check sign",IF(R22<0,"Principal paid exceeds prior balance",IF(AND(L22>Q22,NOT(ISNUMBER(P22))),"Balance increased but no Deferred_interest reported",IF(L22>R22,"Reported balance higher than expected (missing increase/OC build)","Reported balance lower than expected (missing decrease)"))))),"")) -> Reported balance higher than expected (missing increase/OC build)
A23: 35538 | B23: RALI 2005-QS14 | C23: WL | D23: 9 | E23: 2026 | F23: UPLOADED | G23: GMAC_Format_2 | H23: PI | I23: 398893 | J23: III-A-1 | K23: 6387617.8 | L23: 6322456.2 | M23: NULL | N23: 82490.51 | O23: 0 | P23: 0 | Q23: 6387617.8 | R23: =IF(AND(A23<>"",ISNUMBER(Q23),ISNUMBER(L23)),ROUND(Q23-IF(ISNUMBER(N23),N23,0)-IF(ISNUMBER(O23),O23,0)+IF(ISNUMBER(P23),P23,0),2),"") -> 6305127.3 | S23: =IF(R23="","",ROUND(L23-R23,2)) -> 17328.89 | T23: =IF(A23="","",IF(S23="","BYPASS",IF(ABS(S23)<=Summary!$B$2,"PASS","FAIL"))) -> FAIL | U23: =IF(T23="BYPASS",IF(NOT(ISNUMBER(Q23)),"PreV_ETB missing","End_tr_balance missing"),IF(T23="FAIL",IF(AND(ISNUMBER(K23),ISNUMBER(L23),ABS(L23-(K23-IF(ISNUMBER(N23),N23,0)-IF(ISNUMBER(O23),O23,0)+IF(ISNUMBER(P23),P23,0)))<=Summary!$B$2),"Passes using beginning_balance - PreV_ETB differs from beginning_balance",IF(AND(ISNUMBER(O23),O23<0,ABS(L23-(Q23-IF(ISNUMBER(N23),N23,0)+IF(ISNUMBER(P23),P23,0)))<=Summary!$B$2),"Negative realized loss not applied - check sign",IF(R23<0,"Principal paid exceeds prior balance",IF(AND(L23>Q23,NOT(ISNUMBER(P23))),"Balance increased but no Deferred_interest reported",IF(L23>R23,"Reported balance higher than expected (missing increase/OC build)","Reported balance lower than expected (missing decrease)"))))),"")) -> Reported balance higher than expected (missing increase/OC build)
A24: 37098 | B24: GE-WMC 2005-2 | C24: WL | D24: 9 | E24: 2026 | F24: UPLOADED | G24: BNY_FORMAT_2 | H24: PI | I24: 420086 | J24: C | K24: 241828.71 | L24: 216987.04 | M24: NULL | N24: 0 | O24: 0 | P24: NULL | Q24: 241828.71 | R24: =IF(AND(A24<>"",ISNUMBER(Q24),ISNUMBER(L24)),ROUND(Q24-IF(ISNUMBER(N24),N24,0)-IF(ISNUMBER(O24),O24,0)+IF(ISNUMBER(P24),P24,0),2),"") -> 241828.71 | S24: =IF(R24="","",ROUND(L24-R24,2)) -> -24841.67 | T24: =IF(A24="","",IF(S24="","BYPASS",IF(ABS(S24)<=Summary!$B$2,"PASS","FAIL"))) -> FAIL | U24: =IF(T24="BYPASS",IF(NOT(ISNUMBER(Q24)),"PreV_ETB missing","End_tr_balance missing"),IF(T24="FAIL",IF(AND(ISNUMBER(K24),ISNUMBER(L24),ABS(L24-(K24-IF(ISNUMBER(N24),N24,0)-IF(ISNUMBER(O24),O24,0)+IF(ISNUMBER(P24),P24,0)))<=Summary!$B$2),"Passes using beginning_balance - PreV_ETB differs from beginning_balance",IF(AND(ISNUMBER(O24),O24<0,ABS(L24-(Q24-IF(ISNUMBER(N24),N24,0)+IF(ISNUMBER(P24),P24,0)))<=Summary!$B$2),"Negative realized loss not applied - check sign",IF(R24<0,"Principal paid exceeds prior balance",IF(AND(L24>Q24,NOT(ISNUMBER(P24))),"Balance increased but no Deferred_interest reported",IF(L24>R24,"Reported balance higher than expected (missing increase/OC build)","Reported balance lower than expected (missing decrease)"))))),"")) -> Reported balance lower than expected (missing decrease)
A25: 38600 | B25: RAMP 2005-NC1 | C25: WL | D25: 9 | E25: 2026 | F25: UPLOADED | G25: GMAC_Format_2 | H25: PI | I25: 440597 | J25: A-I-3 | K25: 0 | L25: 0 | M25: NULL | N25: 17661.97 | O25: 0 | P25: 0 | Q25: 0 | R25: =IF(AND(A25<>"",ISNUMBER(Q25),ISNUMBER(L25)),ROUND(Q25-IF(ISNUMBER(N25),N25,0)-IF(ISNUMBER(O25),O25,0)+IF(ISNUMBER(P25),P25,0),2),"") -> -17661.97 | S25: =IF(R25="","",ROUND(L25-R25,2)) -> 17661.97 | T25: =IF(A25="","",IF(S25="","BYPASS",IF(ABS(S25)<=Summary!$B$2,"PASS","FAIL"))) -> FAIL | U25: =IF(T25="BYPASS",IF(NOT(ISNUMBER(Q25)),"PreV_ETB missing","End_tr_balance missing"),IF(T25="FAIL",IF(AND(ISNUMBER(K25),ISNUMBER(L25),ABS(L25-(K25-IF(ISNUMBER(N25),N25,0)-IF(ISNUMBER(O25),O25,0)+IF(ISNUMBER(P25),P25,0)))<=Summary!$B$2),"Passes using beginning_balance - PreV_ETB differs from beginning_balance",IF(AND(ISNUMBER(O25),O25<0,ABS(L25-(Q25-IF(ISNUMBER(N25),N25,0)+IF(ISNUMBER(P25),P25,0)))<=Summary!$B$2),"Negative realized loss not applied - check sign",IF(R25<0,"Principal paid exceeds prior balance",IF(AND(L25>Q25,NOT(ISNUMBER(P25))),"Balance increased but no Deferred_interest reported",IF(L25>R25,"Reported balance higher than expected (missing increase/OC build)","Reported balance lower than expected (missing decrease)"))))),"")) -> Principal paid exceeds prior balance
A26: 39951 | B26: Luminent 2006-1 | C26: WL | D26: 9 | E26: 2026 | F26: UPLOADED | G26: DM_BNY_FORMAT_5 | H26: PI | I26: 1511073 | J26: X | K26: 22223587 | L26: 122192.06 | M26: 22032869 | N26: 393.92 | O26: -53.5 | P26: 0 | Q26: 122532.48 | R26: =IF(AND(A26<>"",ISNUMBER(Q26),ISNUMBER(L26)),ROUND(Q26-IF(ISNUMBER(N26),N26,0)-IF(ISNUMBER(O26),O26,0)+IF(ISNUMBER(P26),P26,0),2),"") -> 122192.06 | S26: =IF(R26="","",ROUND(L26-R26,2)) -> 0 | T26: =IF(A26="","",IF(S26="","BYPASS",IF(ABS(S26)<=Summary!$B$2,"PASS","FAIL"))) -> PASS | U26: =IF(T26="BYPASS",IF(NOT(ISNUMBER(Q26)),"PreV_ETB missing","End_tr_balance missing"),IF(T26="FAIL",IF(AND(ISNUMBER(K26),ISNUMBER(L26),ABS(L26-(K26-IF(ISNUMBER(N26),N26,0)-IF(ISNUMBER(O26),O26,0)+IF(ISNUMBER(P26),P26,0)))<=Summary!$B$2),"Passes using beginning_balance - PreV_ETB differs from beginning_balance",IF(AND(ISNUMBER(O26),O26<0,ABS(L26-(Q26-IF(ISNUMBER(N26),N26,0)+IF(ISNUMBER(P26),P26,0)))<=Summary!$B$2),"Negative realized loss not applied - check sign",IF(R26<0,"Principal paid exceeds prior balance",IF(AND(L26>Q26,NOT(ISNUMBER(P26))),"Balance increased but no Deferred_interest reported",IF(L26>R26,"Reported balance higher than expected (missing increase/OC build)","Reported balance lower than expected (missing decrease)"))))),""))
A27: 40869 | B27: WMALT 2007-OA3 | C27: WL | D27: 9 | E27: 2026 | F27: UPLOADED | G27: WAMU_Format_1 | H27: PI | I27: 471679 | J27: CX2PPP | K27: 288663.6 | L27: 286326.04 | M27: 66043707 | N27: 2605.87 | O27: -268.31 | P27: NULL | Q27: 288663.61 | R27: =IF(AND(A27<>"",ISNUMBER(Q27),ISNUMBER(L27)),ROUND(Q27-IF(ISNUMBER(N27),N27,0)-IF(ISNUMBER(O27),O27,0)+IF(ISNUMBER(P27),P27,0),2),"") -> 286326.05 | S27: =IF(R27="","",ROUND(L27-R27,2)) -> -0.01 | T27: =IF(A27="","",IF(S27="","BYPASS",IF(ABS(S27)<=Summary!$B$2,"PASS","FAIL"))) -> PASS | U27: =IF(T27="BYPASS",IF(NOT(ISNUMBER(Q27)),"PreV_ETB missing","End_tr_balance missing"),IF(T27="FAIL",IF(AND(ISNUMBER(K27),ISNUMBER(L27),ABS(L27-(K27-IF(ISNUMBER(N27),N27,0)-IF(ISNUMBER(O27),O27,0)+IF(ISNUMBER(P27),P27,0)))<=Summary!$B$2),"Passes using beginning_balance - PreV_ETB differs from beginning_balance",IF(AND(ISNUMBER(O27),O27<0,ABS(L27-(Q27-IF(ISNUMBER(N27),N27,0)+IF(ISNUMBER(P27),P27,0)))<=Summary!$B$2),"Negative realized loss not applied - check sign",IF(R27<0,"Principal paid exceeds prior balance",IF(AND(L27>Q27,NOT(ISNUMBER(P27))),"Balance increased but no Deferred_interest reported",IF(L27>R27,"Reported balance higher than expected (missing increase/OC build)","Reported balance lower than expected (missing decrease)"))))),""))
A28: 41750 | B28: WMALT 2007-OA2 | C28: WL | D28: 9 | E28: 2026 | F28: UPLOADED | G28: WAMU_Format_1 | H28: PI | I28: 485457 | J28: CX2PPP | K28: 206864.13 | L28: 205486.43 | M28: 205486.43 | N28: 1396.88 | O28: -17.67 | P28: NULL | Q28: 206864.12 | R28: =IF(AND(A28<>"",ISNUMBER(Q28),ISNUMBER(L28)),ROUND(Q28-IF(ISNUMBER(N28),N28,0)-IF(ISNUMBER(O28),O28,0)+IF(ISNUMBER(P28),P28,0),2),"") -> 205484.91 | S28: =IF(R28="","",ROUND(L28-R28,2)) -> 1.52 | T28: =IF(A28="","",IF(S28="","BYPASS",IF(ABS(S28)<=Summary!$B$2,"PASS","FAIL"))) -> FAIL | U28: =IF(T28="BYPASS",IF(NOT(ISNUMBER(Q28)),"PreV_ETB missing","End_tr_balance missing"),IF(T28="FAIL",IF(AND(ISNUMBER(K28),ISNUMBER(L28),ABS(L28-(K28-IF(ISNUMBER(N28),N28,0)-IF(ISNUMBER(O28),O28,0)+IF(ISNUMBER(P28),P28,0)))<=Summary!$B$2),"Passes using beginning_balance - PreV_ETB differs from beginning_balance",IF(AND(ISNUMBER(O28),O28<0,ABS(L28-(Q28-IF(ISNUMBER(N28),N28,0)+IF(ISNUMBER(P28),P28,0)))<=Summary!$B$2),"Negative realized loss not applied - check sign",IF(R28<0,"Principal paid exceeds prior balance",IF(AND(L28>Q28,NOT(ISNUMBER(P28))),"Balance increased but no Deferred_interest reported",IF(L28>R28,"Reported balance higher than expected (missing increase/OC build)","Reported balance lower than expected (missing decrease)"))))),"")) -> Reported balance higher than expected (missing increase/OC build)
A29: 42323 | B29: WaMu 2007-HY1 | C29: WL | D29: 9 | E29: 2026 | F29: UPLOADED | G29: WAMU_Format_1 | H29: PI | I29: 494473 | J29: 1A2 | K29: 0 | L29: 0 | M29: NULL | N29: 2862.86 | O29: 0 | P29: NULL | Q29: 0 | R29: =IF(AND(A29<>"",ISNUMBER(Q29),ISNUMBER(L29)),ROUND(Q29-IF(ISNUMBER(N29),N29,0)-IF(ISNUMBER(O29),O29,0)+IF(ISNUMBER(P29),P29,0),2),"") -> -2862.86 | S29: =IF(R29="","",ROUND(L29-R29,2)) -> 2862.86 | T29: =IF(A29="","",IF(S29="","BYPASS",IF(ABS(S29)<=Summary!$B$2,"PASS","FAIL"))) -> FAIL | U29: =IF(T29="BYPASS",IF(NOT(ISNUMBER(Q29)),"PreV_ETB missing","End_tr_balance missing"),IF(T29="FAIL",IF(AND(ISNUMBER(K29),ISNUMBER(L29),ABS(L29-(K29-IF(ISNUMBER(N29),N29,0)-IF(ISNUMBER(O29),O29,0)+IF(ISNUMBER(P29),P29,0)))<=Summary!$B$2),"Passes using beginning_balance - PreV_ETB differs from beginning_balance",IF(AND(ISNUMBER(O29),O29<0,ABS(L29-(Q29-IF(ISNUMBER(N29),N29,0)+IF(ISNUMBER(P29),P29,0)))<=Summary!$B$2),"Negative realized loss not applied - check sign",IF(R29<0,"Principal paid exceeds prior balance",IF(AND(L29>Q29,NOT(ISNUMBER(P29))),"Balance increased but no Deferred_interest reported",IF(L29>R29,"Reported balance higher than expected (missing increase/OC build)","Reported balance lower than expected (missing decrease)"))))),"")) -> Principal paid exceeds prior balance
A30: 44034 | B30: Security National 2007-1 | C30: WL | D30: 9 | E30: 2026 | F30: UPLOADED | G30: US_Format_26 | H30: PI | I30: 513614 | J30: X | K30: 133680.79 | L30: 142253.17 | M30: NULL | N30: 0 | O30: NULL | P30: 0 | Q30: 133680.79 | R30: =IF(AND(A30<>"",ISNUMBER(Q30),ISNUMBER(L30)),ROUND(Q30-IF(ISNUMBER(N30),N30,0)-IF(ISNUMBER(O30),O30,0)+IF(ISNUMBER(P30),P30,0),2),"") -> 133680.79 | S30: =IF(R30="","",ROUND(L30-R30,2)) -> 8572.38 | T30: =IF(A30="","",IF(S30="","BYPASS",IF(ABS(S30)<=Summary!$B$2,"PASS","FAIL"))) -> FAIL | U30: =IF(T30="BYPASS",IF(NOT(ISNUMBER(Q30)),"PreV_ETB missing","End_tr_balance missing"),IF(T30="FAIL",IF(AND(ISNUMBER(K30),ISNUMBER(L30),ABS(L30-(K30-IF(ISNUMBER(N30),N30,0)-IF(ISNUMBER(O30),O30,0)+IF(ISNUMBER(P30),P30,0)))<=Summary!$B$2),"Passes using beginning_balance - PreV_ETB differs from beginning_balance",IF(AND(ISNUMBER(O30),O30<0,ABS(L30-(Q30-IF(ISNUMBER(N30),N30,0)+IF(ISNUMBER(P30),P30,0)))<=Summary!$B$2),"Negative realized loss not applied - check sign",IF(R30<0,"Principal paid exceeds prior balance",IF(AND(L30>Q30,NOT(ISNUMBER(P30))),"Balance increased but no Deferred_interest reported",IF(L30>R30,"Reported balance higher than expected (missing increase/OC build)","Reported balance lower than expected (missing decrease)"))))),"")) -> Reported balance higher than expected (missing increase/OC build)
A31: 1005667 | B31: FH SCRT 2017-3 | C31: WL | D31: 9 | E31: 2026 | F31: UPLOADED | G31: US_Format_29 | H31: PI | I31: 1548522 | J31: HT | K31: 1.1716616e+08 | L31: 1.1649459e+08 | M31: NULL | N31: 787954.49 | O31: 0 | P31: NULL | Q31: 1.1716616e+08 | R31: =IF(AND(A31<>"",ISNUMBER(Q31),ISNUMBER(L31)),ROUND(Q31-IF(ISNUMBER(N31),N31,0)-IF(ISNUMBER(O31),O31,0)+IF(ISNUMBER(P31),P31,0),2),"") -> 1.163782e+08 | S31: =IF(R31="","",ROUND(L31-R31,2)) -> 116384.69 | T31: =IF(A31="","",IF(S31="","BYPASS",IF(ABS(S31)<=Summary!$B$2,"PASS","FAIL"))) -> FAIL | U31: =IF(T31="BYPASS",IF(NOT(ISNUMBER(Q31)),"PreV_ETB missing","End_tr_balance missing"),IF(T31="FAIL",IF(AND(ISNUMBER(K31),ISNUMBER(L31),ABS(L31-(K31-IF(ISNUMBER(N31),N31,0)-IF(ISNUMBER(O31),O31,0)+IF(ISNUMBER(P31),P31,0)))<=Summary!$B$2),"Passes using beginning_balance - PreV_ETB differs from beginning_balance",IF(AND(ISNUMBER(O31),O31<0,ABS(L31-(Q31-IF(ISNUMBER(N31),N31,0)+IF(ISNUMBER(P31),P31,0)))<=Summary!$B$2),"Negative realized loss not applied - check sign",IF(R31<0,"Principal paid exceeds prior balance",IF(AND(L31>Q31,NOT(ISNUMBER(P31))),"Balance increased but no Deferred_interest reported",IF(L31>R31,"Reported balance higher than expected (missing increase/OC build)","Reported balance lower than expected (missing decrease)"))))),"")) -> Reported balance higher than expected (missing increase/OC build)
A32: 1006441 | B32: FH SCRT 2018-1 | C32: WL | D32: 9 | E32: 2026 | F32: UPLOADED | G32: US_Format_29 | H32: PI | I32: 1554724 | J32: HB | K32: 10500000 | L32: 10500000 | M32: NULL | N32: 16722.04 | O32: 0 | P32: NULL | Q32: 10500000 | R32: =IF(AND(A32<>"",ISNUMBER(Q32),ISNUMBER(L32)),ROUND(Q32-IF(ISNUMBER(N32),N32,0)-IF(ISNUMBER(O32),O32,0)+IF(ISNUMBER(P32),P32,0),2),"") -> 10483278 | S32: =IF(R32="","",ROUND(L32-R32,2)) -> 16722.04 | T32: =IF(A32="","",IF(S32="","BYPASS",IF(ABS(S32)<=Summary!$B$2,"PASS","FAIL"))) -> FAIL | U32: =IF(T32="BYPASS",IF(NOT(ISNUMBER(Q32)),"PreV_ETB missing","End_tr_balance missing"),IF(T32="FAIL",IF(AND(ISNUMBER(K32),ISNUMBER(L32),ABS(L32-(K32-IF(ISNUMBER(N32),N32,0)-IF(ISNUMBER(O32),O32,0)+IF(ISNUMBER(P32),P32,0)))<=Summary!$B$2),"Passes using beginning_balance - PreV_ETB differs from beginning_balance",IF(AND(ISNUMBER(O32),O32<0,ABS(L32-(Q32-IF(ISNUMBER(N32),N32,0)+IF(ISNUMBER(P32),P32,0)))<=Summary!$B$2),"Negative realized loss not applied - check sign",IF(R32<0,"Principal paid exceeds prior balance",IF(AND(L32>Q32,NOT(ISNUMBER(P32))),"Balance increased but no Deferred_interest reported",IF(L32>R32,"Reported balance higher than expected (missing increase/OC build)","Reported balance lower than expected (missing decrease)"))))),"")) -> Reported balance higher than expected (missing increase/OC build)
A33: 1014725 | B33: Verus 2022-3 | C33: WL | D33: 9 | E33: 2026 | F33: UPLOADED | G33: CM_Format_2 | H33: PI | I33: 1646045 | J33: A1 | K33: 2.7873987e+08 | L33: 2.7435371e+08 | M33: NULL | N33: 4386161.3 | O33: 0 | P33: 0 | Q33: 2.7870847e+08 | R33: =IF(AND(A33<>"",ISNUMBER(Q33),ISNUMBER(L33)),ROUND(Q33-IF(ISNUMBER(N33),N33,0)-IF(ISNUMBER(O33),O33,0)+IF(ISNUMBER(P33),P33,0),2),"") -> 2.7432231e+08 | S33: =IF(R33="","",ROUND(L33-R33,2)) -> 31394.35 | T33: =IF(A33="","",IF(S33="","BYPASS",IF(ABS(S33)<=Summary!$B$2,"PASS","FAIL"))) -> FAIL | U33: =IF(T33="BYPASS",IF(NOT(ISNUMBER(Q33)),"PreV_ETB missing","End_tr_balance missing"),IF(T33="FAIL",IF(AND(ISNUMBER(K33),ISNUMBER(L33),ABS(L33-(K33-IF(ISNUMBER(N33),N33,0)-IF(ISNUMBER(O33),O33,0)+IF(ISNUMBER(P33),P33,0)))<=Summary!$B$2),"Passes using beginning_balance - PreV_ETB differs from beginning_balance",IF(AND(ISNUMBER(O33),O33<0,ABS(L33-(Q33-IF(ISNUMBER(N33),N33,0)+IF(ISNUMBER(P33),P33,0)))<=Summary!$B$2),"Negative realized loss not applied - check sign",IF(R33<0,"Principal paid exceeds prior balance",IF(AND(L33>Q33,NOT(ISNUMBER(P33))),"Balance increased but no Deferred_interest reported",IF(L33>R33,"Reported balance higher than expected (missing increase/OC build)","Reported balance lower than expected (missing decrease)"))))),"")) -> Reported balance higher than expected (missing increase/OC build)
A34: 1015921 | B34: Walsh 1997-2 | C34: WL | D34: 9 | E34: 2026 | F34: UPLOADED | G34: DB_FORMAT_1 | H34: PI | I34: 1659319 | J34: A | K34: 6642.86 | L34: 5208.58 | M34: NULL | N34: 1451.23 | O34: 0 | P34: 16.95 | Q34: 6642.86 | R34: =IF(AND(A34<>"",ISNUMBER(Q34),ISNUMBER(L34)),ROUND(Q34-IF(ISNUMBER(N34),N34,0)-IF(ISNUMBER(O34),O34,0)+IF(ISNUMBER(P34),P34,0),2),"") -> 5208.58 | S34: =IF(R34="","",ROUND(L34-R34,2)) -> 0 | T34: =IF(A34="","",IF(S34="","BYPASS",IF(ABS(S34)<=Summary!$B$2,"PASS","FAIL"))) -> PASS | U34: =IF(T34="BYPASS",IF(NOT(ISNUMBER(Q34)),"PreV_ETB missing","End_tr_balance missing"),IF(T34="FAIL",IF(AND(ISNUMBER(K34),ISNUMBER(L34),ABS(L34-(K34-IF(ISNUMBER(N34),N34,0)-IF(ISNUMBER(O34),O34,0)+IF(ISNUMBER(P34),P34,0)))<=Summary!$B$2),"Passes using beginning_balance - PreV_ETB differs from beginning_balance",IF(AND(ISNUMBER(O34),O34<0,ABS(L34-(Q34-IF(ISNUMBER(N34),N34,0)+IF(ISNUMBER(P34),P34,0)))<=Summary!$B$2),"Negative realized loss not applied - check sign",IF(R34<0,"Principal paid exceeds prior balance",IF(AND(L34>Q34,NOT(ISNUMBER(P34))),"Balance increased but no Deferred_interest reported",IF(L34>R34,"Reported balance higher than expected (missing increase/OC build)","Reported balance lower than expected (missing decrease)"))))),""))
A35: 1016252 | B35: FoA Structured 2022-S4 | C35: WL | D35: 9 | E35: 2026 | F35: UPLOADED | G35: US_Format_26 | H35: PI | I35: 1661317 | J35: A1B | K35: 48699946 | L35: 0 | M35: NULL | N35: 48801405 | O35: NULL | P35: NULL | Q35: 48699946 | R35: =IF(AND(A35<>"",ISNUMBER(Q35),ISNUMBER(L35)),ROUND(Q35-IF(ISNUMBER(N35),N35,0)-IF(ISNUMBER(O35),O35,0)+IF(ISNUMBER(P35),P35,0),2),"") -> -101458.22 | S35: =IF(R35="","",ROUND(L35-R35,2)) -> 101458.22 | T35: =IF(A35="","",IF(S35="","BYPASS",IF(ABS(S35)<=Summary!$B$2,"PASS","FAIL"))) -> FAIL | U35: =IF(T35="BYPASS",IF(NOT(ISNUMBER(Q35)),"PreV_ETB missing","End_tr_balance missing"),IF(T35="FAIL",IF(AND(ISNUMBER(K35),ISNUMBER(L35),ABS(L35-(K35-IF(ISNUMBER(N35),N35,0)-IF(ISNUMBER(O35),O35,0)+IF(ISNUMBER(P35),P35,0)))<=Summary!$B$2),"Passes using beginning_balance - PreV_ETB differs from beginning_balance",IF(AND(ISNUMBER(O35),O35<0,ABS(L35-(Q35-IF(ISNUMBER(N35),N35,0)+IF(ISNUMBER(P35),P35,0)))<=Summary!$B$2),"Negative realized loss not applied - check sign",IF(R35<0,"Principal paid exceeds prior balance",IF(AND(L35>Q35,NOT(ISNUMBER(P35))),"Balance increased but no Deferred_interest reported",IF(L35>R35,"Reported balance higher than expected (missing increase/OC build)","Reported balance lower than expected (missing decrease)"))))),"")) -> Principal paid exceeds prior balance
A36: 1021920 | B36: Station Place 2025-3 | C36: WL | D36: 9 | E36: 2026 | F36: UPLOADED | G36: US_Format_24 | H36: PI | I36: 1709543 | J36: Certificates | K36: 100 | L36: 0 | M36: NULL | N36: 0 | O36: 0 | P36: NULL | Q36: 100 | R36: =IF(AND(A36<>"",ISNUMBER(Q36),ISNUMBER(L36)),ROUND(Q36-IF(ISNUMBER(N36),N36,0)-IF(ISNUMBER(O36),O36,0)+IF(ISNUMBER(P36),P36,0),2),"") -> 100 | S36: =IF(R36="","",ROUND(L36-R36,2)) -> -100 | T36: =IF(A36="","",IF(S36="","BYPASS",IF(ABS(S36)<=Summary!$B$2,"PASS","FAIL"))) -> FAIL | U36: =IF(T36="BYPASS",IF(NOT(ISNUMBER(Q36)),"PreV_ETB missing","End_tr_balance missing"),IF(T36="FAIL",IF(AND(ISNUMBER(K36),ISNUMBER(L36),ABS(L36-(K36-IF(ISNUMBER(N36),N36,0)-IF(ISNUMBER(O36),O36,0)+IF(ISNUMBER(P36),P36,0)))<=Summary!$B$2),"Passes using beginning_balance - PreV_ETB differs from beginning_balance",IF(AND(ISNUMBER(O36),O36<0,ABS(L36-(Q36-IF(ISNUMBER(N36),N36,0)+IF(ISNUMBER(P36),P36,0)))<=Summary!$B$2),"Negative realized loss not applied - check sign",IF(R36<0,"Principal paid exceeds prior balance",IF(AND(L36>Q36,NOT(ISNUMBER(P36))),"Balance increased but no Deferred_interest reported",IF(L36>R36,"Reported balance higher than expected (missing increase/OC build)","Reported balance lower than expected (missing decrease)"))))),"")) -> Reported balance lower than expected (missing decrease)
A37: 1024316 | B37: Citigroup 2026-RP2 | C37: WL | D37: 9 | E37: 2026 | F37: UPLOADED | G37: US_Format_24 | H37: PI | I37: 1733500 | J37: A-1 | K37: 4.6575964e+08 | L37: 4.647172e+08 | M37: NULL | N37: 1042437.1 | O37: 0 | P37: NULL | Q37: 4.6567098e+08 | R37: =IF(AND(A37<>"",ISNUMBER(Q37),ISNUMBER(L37)),ROUND(Q37-IF(ISNUMBER(N37),N37,0)-IF(ISNUMBER(O37),O37,0)+IF(ISNUMBER(P37),P37,0),2),"") -> 4.6462854e+08 | S37: =IF(R37="","",ROUND(L37-R37,2)) -> 88660.39 | T37: =IF(A37="","",IF(S37="","BYPASS",IF(ABS(S37)<=Summary!$B$2,"PASS","FAIL"))) -> FAIL | U37: =IF(T37="BYPASS",IF(NOT(ISNUMBER(Q37)),"PreV_ETB missing","End_tr_balance missing"),IF(T37="FAIL",IF(AND(ISNUMBER(K37),ISNUMBER(L37),ABS(L37-(K37-IF(ISNUMBER(N37),N37,0)-IF(ISNUMBER(O37),O37,0)+IF(ISNUMBER(P37),P37,0)))<=Summary!$B$2),"Passes using beginning_balance - PreV_ETB differs from beginning_balance",IF(AND(ISNUMBER(O37),O37<0,ABS(L37-(Q37-IF(ISNUMBER(N37),N37,0)+IF(ISNUMBER(P37),P37,0)))<=Summary!$B$2),"Negative realized loss not applied - check sign",IF(R37<0,"Principal paid exceeds prior balance",IF(AND(L37>Q37,NOT(ISNUMBER(P37))),"Balance increased but no Deferred_interest reported",IF(L37>R37,"Reported balance higher than expected (missing increase/OC build)","Reported balance lower than expected (missing decrease)"))))),"")) -> Passes using beginning_balance - PreV_ETB differs from beginning_balance
A38: 33971 | B38: Countrywide ALT 2005-24 | C38: WL | D38: 9 | E38: 2026 | F38: UPLOADED | G38: BNY_FORMAT_4 | H38: PI | I38: 1512311 | J38: 1AX | K38: 4654640.9 | L38: 4352.66 | M38: 4620933.6 | N38: 27.62 | O38: 0 | P38: 0 | Q38: 4380.28 | R38: =IF(AND(A38<>"",ISNUMBER(Q38),ISNUMBER(L38)),ROUND(Q38-IF(ISNUMBER(N38),N38,0)-IF(ISNUMBER(O38),O38,0)+IF(ISNUMBER(P38),P38,0),2),"") -> 4352.66 | S38: =IF(R38="","",ROUND(L38-R38,2)) -> 0 | T38: =IF(A38="","",IF(S38="","BYPASS",IF(ABS(S38)<=Summary!$B$2,"PASS","FAIL"))) -> PASS | U38: =IF(T38="BYPASS",IF(NOT(ISNUMBER(Q38)),"PreV_ETB missing","End_tr_balance missing"),IF(T38="FAIL",IF(AND(ISNUMBER(K38),ISNUMBER(L38),ABS(L38-(K38-IF(ISNUMBER(N38),N38,0)-IF(ISNUMBER(O38),O38,0)+IF(ISNUMBER(P38),P38,0)))<=Summary!$B$2),"Passes using beginning_balance - PreV_ETB differs from beginning_balance",IF(AND(ISNUMBER(O38),O38<0,ABS(L38-(Q38-IF(ISNUMBER(N38),N38,0)+IF(ISNUMBER(P38),P38,0)))<=Summary!$B$2),"Negative realized loss not applied - check sign",IF(R38<0,"Principal paid exceeds prior balance",IF(AND(L38>Q38,NOT(ISNUMBER(P38))),"Balance increased but no Deferred_interest reported",IF(L38>R38,"Reported balance higher than expected (missing increase/OC build)","Reported balance lower than expected (missing decrease)"))))),""))
A39: 500010106 | B39: Ocwen RMBS 1999-R2 | C39: WL | D39: 9 | E39: 2026 | F39: UPLOADED | G39: DM_US_Format_1 | H39: IO | I39: 500036842 | J39: AP | K39: 712816.61 | L39: 706923.02 | M39: 706923.02 | N39: 5754.43 | O39: 139.16 | P39: 0 | Q39: 712816.61 | R39: =IF(AND(A39<>"",ISNUMBER(Q39),ISNUMBER(L39)),ROUND(Q39-IF(ISNUMBER(N39),N39,0)-IF(ISNUMBER(O39),O39,0)+IF(ISNUMBER(P39),P39,0),2),"") -> 706923.02 | S39: =IF(R39="","",ROUND(L39-R39,2)) -> 0 | T39: =IF(A39="","",IF(S39="","BYPASS",IF(ABS(S39)<=Summary!$B$2,"PASS","FAIL"))) -> PASS | U39: =IF(T39="BYPASS",IF(NOT(ISNUMBER(Q39)),"PreV_ETB missing","End_tr_balance missing"),IF(T39="FAIL",IF(AND(ISNUMBER(K39),ISNUMBER(L39),ABS(L39-(K39-IF(ISNUMBER(N39),N39,0)-IF(ISNUMBER(O39),O39,0)+IF(ISNUMBER(P39),P39,0)))<=Summary!$B$2),"Passes using beginning_balance - PreV_ETB differs from beginning_balance",IF(AND(ISNUMBER(O39),O39<0,ABS(L39-(Q39-IF(ISNUMBER(N39),N39,0)+IF(ISNUMBER(P39),P39,0)))<=Summary!$B$2),"Negative realized loss not applied - check sign",IF(R39<0,"Principal paid exceeds prior balance",IF(AND(L39>Q39,NOT(ISNUMBER(P39))),"Balance increased but no Deferred_interest reported",IF(L39>R39,"Reported balance higher than expected (missing increase/OC build)","Reported balance lower than expected (missing decrease)"))))),""))
A40: 500019189 | B40: CIT HEL 2002-1 | C40: WL | D40: 9 | E40: 2026 | F40: UPLOADED | G40: Other_Format_4 | H40: PI | I40: 500080113 | J40: Cl. MV-2 | K40: 781251.21 | L40: 680518.53 | M40: NULL | N40: 108331.84 | O40: 0 | P40: 0 | Q40: 781251.21 | R40: =IF(AND(A40<>"",ISNUMBER(Q40),ISNUMBER(L40)),ROUND(Q40-IF(ISNUMBER(N40),N40,0)-IF(ISNUMBER(O40),O40,0)+IF(ISNUMBER(P40),P40,0),2),"") -> 672919.37 | S40: =IF(R40="","",ROUND(L40-R40,2)) -> 7599.16 | T40: =IF(A40="","",IF(S40="","BYPASS",IF(ABS(S40)<=Summary!$B$2,"PASS","FAIL"))) -> FAIL | U40: =IF(T40="BYPASS",IF(NOT(ISNUMBER(Q40)),"PreV_ETB missing","End_tr_balance missing"),IF(T40="FAIL",IF(AND(ISNUMBER(K40),ISNUMBER(L40),ABS(L40-(K40-IF(ISNUMBER(N40),N40,0)-IF(ISNUMBER(O40),O40,0)+IF(ISNUMBER(P40),P40,0)))<=Summary!$B$2),"Passes using beginning_balance - PreV_ETB differs from beginning_balance",IF(AND(ISNUMBER(O40),O40<0,ABS(L40-(Q40-IF(ISNUMBER(N40),N40,0)+IF(ISNUMBER(P40),P40,0)))<=Summary!$B$2),"Negative realized loss not applied - check sign",IF(R40<0,"Principal paid exceeds prior balance",IF(AND(L40>Q40,NOT(ISNUMBER(P40))),"Balance increased but no Deferred_interest reported",IF(L40>R40,"Reported balance higher than expected (missing increase/OC build)","Reported balance lower than expected (missing decrease)"))))),"")) -> Reported balance higher than expected (missing increase/OC build)
...
